例外が発生しなかった場合。
dca
tryでブロックex1呼び出し->ex1の中でex2呼び出し（dを出力)、cを出力->tryブロックでaを出力


例外が発生した場合。
b
ex1で例外発生、RuntimeException->メソッド呼び出し元のcatch文で処理、bを出力